Workbook

Sheet README
A1: Citi Onboarding Operations Pack
A2: Label | B2: Simulated workflow on real GLEIF entity data. Not Citi data.
A3: Simulation clock | B3: 2026-10-30 18:00:00
A4: Entity data | B4: Real public GLEIF Golden Copy, published 2026-10-04 16:00
A5: Requests, errors, SLAs, staffing | B5: Simulated assumptions (baseline 6 makers, 3 checkers in the workflow simulation; log IDs M1-M8 and C1-C4 in Lodgment_Log are a separate simulated set
A6: Version | B6: v0.1
A8: Test data | B8: Lodgment_Log rows 12 to 17 and Archive_Manifest rows 14 and 15 are deliberate test cases (returned, rejected, pending, and two deliberate errors that fire the red flags). All maker IDs, checker IDs, dates and document types are simulated.
A9: Known limitation | B9: The workbook does not block a checker who is the same person as the maker, but it flags it with "CHECK: maker equals checker" on Checker_Log (tested: maker M3 with checker M3 fires the flag, M3 with C1 does not). Blocking it outright would need a validation rule or procedure.
A10: Backup | B10: The workbook before the fill step is saved as OLD_before_fill_DO_NOT_EDIT.xlsx. Rerun fill_lodgment_archive.py from that file, not from the main file.

Sheet Data_Requests
A1: request_id | B1: lei | C1: request_type | D1: received_ts | E1: due_ts | F1: maker_id | G1: checker_id | H1: maker_done_ts | I1: completed_ts | J1: status | K1: tat_hours | L1: sla_hours | M1: sla_breached | N1: rework_count | O1: first_time_right | P1: has_error | Q1: escalated
A2: REQ00001 | B2: 7245008AVDPCXEZED844 | C2: new_account | D2: 46296.375 | E2: 46297.667 | F2: M1 | G2: C2 | H2: 46296.4 | I2: 46296.412 | J2: Completed | K2: 0.88 | L2: 16 | M2: FALSE | N2: 0 | O2: TRUE | P2: FALSE | Q2: FALSE
A3: REQ00002 | B3: 391200DTW567Q0CC5337 | C3: data_amendment | D3: 46296.375 | E3: 46296.708 | F3: M2 | G3: C1 | H3: 46296.385 | I3: 46296.391 | J3: Completed | K3: 0.38 | L3: 8 | M3: FALSE | N3: 0 | O3: TRUE | P3: FALSE | Q3: FALSE
A4: REQ00003 | B4: 33580094GI2D22DUBG63 | C4: document_refresh | D4: 46296.376 | E4: 46297.501 | F4: M3 | G4: C2 | H4: 46296.393 | I4: 46296.399 | J4: Completed | K4: 0.54 | L4: 12 | M4: FALSE | N4: 0 | O4: TRUE | P4: FALSE | Q4: FALSE
A5: REQ00004 | B5: 984500NCB5BB8EF72J76 | C5: data_amendment | D5: 46296.383 | E5: 46296.716 | F5: M4 | G5: C3 | H5: 46296.394 | I5: 46296.399 | J5: Completed | K5: 0.4 | L5: 8 | M5: FALSE | N5: 0 | O5: TRUE | P5: FALSE | Q5: FALSE
A6: REQ00005 | B6: 213800XVLOZKGP81ZI53 | C6: new_account | D6: 46296.387 | E6: 46297.678 | F6: M5 | G6: C1 | H6: 46296.418 | I6: 46296.519 | J6: Completed | K6: 3.16 | L6: 16 | M6: FALSE | N6: 0 | O6: TRUE | P6: FALSE | Q6: TRUE
A7: REQ00006 | B7: 984500708CB736A0ED48 | C7: data_amendment | D7: 46296.387 | E7: 46296.72 | F7: M6 | G7: C1 | H7: 46296.397 | I7: 46296.4 | J7: Completed | K7: 0.31 | L7: 8 | M7: FALSE | N7: 0 | O7: TRUE | P7: FALSE | Q7: FALSE
A8: REQ00007 | B8: 724500SG3GVRK0421P33 | C8: signatory_change | D8: 46296.39 | E8: 46296.723 | F8: M2 | G8: C3 | H8: 46296.41 | I8: 46296.417 | J8: Completed | K8: 0.67 | L8: 8 | M8: FALSE | N8: 0 | O8: TRUE | P8: FALSE | Q8: FALSE
A9: REQ00008 | B9: 969500JE7JKVI0BQMJ44 | C9: document_refresh | D9: 46296.394 | E9: 46297.519 | F9: M3 | G9: C2 | H9: 46296.406 | I9: 46296.657 | J9: Completed | K9: 6.29 | L9: 12 | M9: FALSE | N9: 0 | O9: TRUE | P9: FALSE | Q9: TRUE
A10: REQ00009 | B10: 213800C6DB11H3EKSL04 | C10: signatory_change | D10: 46296.402 | E10: 46296.735 | F10: M4 | G10: C1 | H10: 46296.428 | I10: 46296.562 | J10: Completed | K10: 3.85 | L10: 8 | M10: FALSE | N10: 0 | O10: TRUE | P10: FALSE | Q10: TRUE
A11: REQ00010 | B11: 549300686A4NGWA2UM65 | C11: new_account | D11: 46296.403 | E11: 46297.695 | F11: M6 | G11: C3 | H11: 46296.443 | I11: 46296.66 | J11: Completed | K11: 6.17 | L11: 16 | M11: FALSE | N11: 0 | O11: TRUE | P11: FALSE | Q11: TRUE
A12: REQ00011 | B12: 984500383FE41EDBA676 | C12: new_account | D12: 46296.404 | E12: 46297.696 | F12: M1 | G12: C3 | H12: 46296.435 | I12: 46296.448 | J12: Completed | K12: 1.06 | L12: 16 | M12: FALSE | N12: 0 | O12: TRUE | P12: FALSE | Q12: FALSE
A13: REQ00012 | B13: 213800KOHI1WL1J84V10 | C13: document_refresh | D13: 46296.404 | E13: 46297.529 | F13: M3 | G13: C1 | H13: 46296.418 | I13: 46296.422 | J13: Completed | K13: 0.44 | L13: 12 | M13: FALSE | N13: 0 | O13: TRUE | P13: FALSE | Q13: FALSE
... A1951: REQ01950 | B1951: 335800T16H469PQX4S25 | C1951: document_refresh | D1951: 46325.526 | E1951: 46328.651 | F1951: M6 | G1951: C2 | H1951: 46325.537 | I1951: 46325.547 | J1951: Completed | K1951: 0.49 | L1951: 12 | M1951: FALSE | N1951: 0 | O1951: TRUE | P1951: FALSE | Q1951: FALSE
A1952: REQ01951 | B1952: 549300U3KTIXS510LL58 | C1952: new_account | D1952: 46325.526 | E1952: 46329.442 | F1952: M1 | G1952: C2 | H1952: 46325.549 | J1952: Open | L1952: 16 | Q1952: TRUE
A1953: REQ01952 | B1953: 984500C761F978656758 | C1953: new_account | D1953: 46325.526 | E1953: 46329.443 | F1953: M3 | G1953: C1 | H1953: 46325.555 | I1953: 46325.569 | J1953: Completed | K1953: 1.02 | L1953: 16 | M1953: FALSE | N1953: 0 | O1953: TRUE | P1953: FALSE | Q1953: FALSE
A1954: REQ01953 | B1954: 724500Y95N7LO8E19A03 | C1954: document_refresh | D1954: 46325.531 | E1954: 46328.656 | F1954: M5 | G1954: C1 | H1954: 46325.545 | I1954: 46325.692 | J1954: Completed | K1954: 3.86 | L1954: 12 | M1954: FALSE | N1954: 0 | O1954: TRUE | P1954: FALSE | Q1954: TRUE
A1955: REQ01954 | B1955: 967600PKRKW8F7JKQT83 | C1955: document_refresh | D1955: 46325.535 | E1955: 46328.66 | F1955: M2 | G1955: C1 | H1955: 46325.544 | I1955: 46325.551 | J1955: Completed | K1955: 0.39 | L1955: 12 | M1955: FALSE | N1955: 0 | O1955: TRUE | P1955: FALSE | Q1955: FALSE
A1956: REQ01955 | B1956: 724500KIFFQ7CZ7E2349 | C1956: document_refresh | D1956: 46325.538 | E1956: 46328.663 | F1956: M6 | G1956: C2 | H1956: 46325.555 | I1956: 46325.561 | J1956: Completed | K1956: 0.55 | L1956: 12 | M1956: FALSE | N1956: 0 | O1956: TRUE | P1956: FALSE | Q1956: FALSE
A1957: REQ01956 | B1957: 5299006PXG54CJ020F45 | C1957: new_account | D1957: 46325.542 | E1957: 46329.458 | F1957: M2 | G1957: C3 | H1957: 46325.578 | I1957: 46325.689 | J1957: Completed | K1957: 3.54 | L1957: 16 | M1957: FALSE | N1957: 0 | O1957: TRUE | P1957: FALSE | Q1957: TRUE
A1958: REQ01957 | B1958: 549300WPKQ51OPEQNJ94 | C1958: new_account | D1958: 46325.551 | E1958: 46329.467 | F1958: M5 | G1958: C1 | H1958: 46325.586 | J1958: Open | L1958: 16 | Q1958: TRUE
A1959: REQ01958 | B1959: 5067002E9XESLN4AG690 | C1959: new_account | D1959: 46325.555 | E1959: 46329.472 | F1959: M1 | G1959: C3 | H1959: 46325.582 | I1959: 46325.611 | J1959: Completed | K1959: 1.35 | L1959: 16 | M1959: FALSE | N1959: 1 | O1959: FALSE | P1959: TRUE | Q1959: FALSE
A1960: REQ01959 | B1960: 6488B6W6T9Z41QZ6C145 | C1960: document_refresh | D1960: 46325.558 | E1960: 46328.683 | F1960: M6 | G1960: C1 | H1960: 46325.576 | I1960: 46325.583 | J1960: Completed | K1960: 0.59 | L1960: 12 | M1960: FALSE | N1960: 0 | O1960: TRUE | P1960: FALSE | Q1960: FALSE
A1961: REQ01960 | B1961: 25490061M5YV739O2V36 | C1961: data_amendment | D1961: 46325.564 | E1961: 46328.522 | F1961: M3 | G1961: C2 | H1961: 46325.576 | I1961: 46325.581 | J1961: Completed | K1961: 0.42 | L1961: 8 | M1961: FALSE | N1961: 0 | O1961: TRUE | P1961: FALSE | Q1961: FALSE
A1962: REQ01961 | B1962: 21380028UFOFCNOKAN57 | C1962: new_account | D1962: 46325.584 | E1962: 46329.501 | F1962: M4 | G1962: C2 | H1962: 46325.624 | J1962: Open | L1962: 16 | Q1962: TRUE
A1963: REQ01962 | B1963: 213800DW8SI3ORBKF348 | C1963: new_account | D1963: 46325.596 | E1963: 46329.512 | F1963: M6 | G1963: C1 | H1963: 46325.635 | I1963: 46325.648 | J1963: Completed | K1963: 1.25 | L1963: 16 | M1963: FALSE | N1963: 0 | O1963: TRUE | P1963: FALSE | Q1963: FALSE
A1964: REQ01963 | B1964: 724500KQBNE1V85UX769 | C1964: document_refresh | D1964: 46325.6 | E1964: 46328.725 | F1964: M3 | G1964: C2 | H1964: 46325.613 | I1964: 46325.619 | J1964: Completed | K1964: 0.47 | L1964: 12 | M1964: FALSE | N1964: 0 | O1964: TRUE | P1964: FALSE | Q1964: FALSE
A1965: REQ01964 | B1965: 2549009UTNWRFTYYLS82 | C1965: document_refresh | D1965: 46325.607 | E1965: 46328.732 | F1965: M2 | G1965: C3 | H1965: 46325.624 | I1965: 46325.631 | J1965: Completed | K1965: 0.58 | L1965: 12 | M1965: FALSE | N1965: 0 | O1965: TRUE | P1965: FALSE | Q1965: FALSE
A1966: REQ01965 | B1966: 9845009V1FBD05C83E19 | C1966: new_account | D1966: 46325.608 | E1966: 46329.525 | F1966: M1 | G1966: C1 | H1966: 46325.647 | J1966: Open | L1966: 16 | Q1966: TRUE
A1967: REQ01966 | B1967: 984500EKEBFD4BHB6933 | C1967: new_account | D1967: 46325.61 | E1967: 46329.526 | F1967: M5 | G1967: C1 | H1967: 46325.649 | I1967: 46325.656 | J1967: Completed | K1967: 1.11 | L1967: 16 | M1967: FALSE | N1967: 0 | O1967: TRUE | P1967: FALSE | Q1967: FALSE
A1968: REQ01967 | B1968: 391200IMWO12OC3F1120 | C1968: new_account | D1968: 46325.612 | E1968: 46329.528 | F1968: M3 | G1968: C2 | H1968: 46325.637 | I1968: 46325.647 | J1968: Completed | K1968: 0.84 | L1968: 16 | M1968: FALSE | N1968: 0 | O1968: TRUE | P1968: FALSE | Q1968: FALSE
A1969: REQ01968 | B1969: 6488U84R8Z5I8ZBY0278 | C1969: new_account | D1969: 46325.613 | E1969: 46329.529 | F1969: M4 | G1969: C2 | H1969: 46325.664 | I1969: 46325.677 | J1969: Completed | K1969: 1.55 | L1969: 16 | M1969: FALSE | N1969: 0 | O1969: TRUE | P1969: FALSE | Q1969: FALSE
A1970: REQ01969 | B1970: 984500FC84D939858695 | C1970: document_refresh | D1970: 46325.613 | E1970: 46328.738 | F1970: M2 | G1970: C3 | H1970: 46325.642 | I1970: 46325.647 | J1970: Completed | K1970: 0.82 | L1970: 12 | M1970: FALSE | N1970: 0 | O1970: TRUE | P1970: FALSE | Q1970: FALSE
A1971: REQ01970 | B1971: 33580068UF4PJ8DSE754 | C1971: data_amendment | D1971: 46325.617 | E1971: 46328.575 | F1971: M6 | G1971: C2 | H1971: 46325.644 | I1971: 46325.651 | J1971: Completed | K1971: 0.81 | L1971: 8 | M1971: FALSE | N1971: 0 | O1971: TRUE | P1971: FALSE | Q1971: FALSE
A1972: REQ01971 | B1972: 5493007MO3WVGVPYES14 | C1972: signatory_change | D1972: 46325.617 | E1972: 46328.576 | F1972: M3 | G1972: C3 | H1972: 46325.658 | J1972: Open | L1972: 8 | Q1972: TRUE
A1973: REQ01972 | B1973: 9845007BFCF368F96D71 | C1973: signatory_change | D1973: 46325.623 | E1973: 46328.581 | F1973: M2 | G1973: C1 | H1973: 46325.665 | I1973: 46325.673 | J1973: Completed | K1973: 1.21 | L1973: 8 | M1973: FALSE | N1973: 0 | O1973: TRUE | P1973: FALSE | Q1973: FALSE
A1974: REQ01973 | B1974: 724500ZWIDWEEEVLF636 | C1974: signatory_change | D1974: 46325.63 | E1974: 46328.588 | F1974: M6 | G1974: C1 | H1974: 46325.662 | I1974: 46325.668 | J1974: Completed | K1974: 0.92 | L1974: 8 | M1974: FALSE | N1974: 0 | O1974: TRUE | P1974: FALSE | Q1974: FALSE
A1975: REQ01974 | B1975: 335800NSIVUEIR6FJ268 | C1975: new_account | D1975: 46325.634 | E1975: 46329.551 | F1975: M1 | G1975: C2 | H1975: 46325.679 | J1975: Open | L1975: 16 | Q1975: TRUE
A1976: REQ01975 | B1976: 254900NJOSEUHIQGYF69 | C1976: document_refresh | D1976: 46325.639 | E1976: 46329.389 | F1976: M5 | G1976: C3 | H1976: 46325.665 | I1976: 46325.678 | J1976: Completed | K1976: 0.96 | L1976: 12 | M1976: FALSE | N1976: 0 | O1976: TRUE | P1976: FALSE | Q1976: FALSE
A1977: REQ01976 | B1977: 3358005OFE58DX7BK626 | C1977: document_refresh | D1977: 46325.641 | E1977: 46329.391 | F1977: M3 | G1977: C1 | H1977: 46325.672 | I1977: 46325.687 | J1977: Completed | K1977: 1.11 | L1977: 12 | M1977: FALSE | N1977: 0 | O1977: TRUE | P1977: FALSE | Q1977: FALSE
...

Sheet Lists
A1: error_code | B1: description
A2: R08 | B2: Required document missing
A3: R09 | B3: Document expired
A4: R10 | B4: Signatory authority evidence missing
A5: R11 | B5: Form name differs from registry name
A6: R12 | B6: Data entry error

Sheet Daily_Queue
A1: Simulation clock | B1: 46325.75 | C1: Hours left = calendar hours to due time. Priority bands are my assumption.
A3: request_id | B3: request_type | C3: received_ts | D3: due_ts | E3: maker_id | F3: hours_left | G3: priority_band | H3: action_status
A4: REQ01971 | B4: signatory_change | C4: 46325.617 | D4: 46328.576 | E4: M3 | F4: =(D4-$B$1)*24 | G4: =IF(F4<0,"P0 Overdue",IF(F4<24,"P1 under 24h",IF(F4<72,"P2 under 72h","P3 later"))) | H4: Not started
A5: REQ01980 | B5: data_amendment | C5: 46325.656 | D5: 46328.615 | E5: M5 | F5: =(D5-$B$1)*24 | G5: =IF(F5<0,"P0 Overdue",IF(F5<24,"P1 under 24h",IF(F5<72,"P2 under 72h","P3 later"))) | H5: Not started
A6: REQ01983 | B6: data_amendment | C6: 46325.673 | D6: 46328.631 | E6: M5 | F6: =(D6-$B$1)*24 | G6: =IF(F6<0,"P0 Overdue",IF(F6<24,"P1 under 24h",IF(F6<72,"P2 under 72h","P3 later"))) | H6: Not started
A7: REQ01988 | B7: data_amendment | C7: 46325.683 | D7: 46328.641 | E7: M5 | F7: =(D7-$B$1)*24 | G7: =IF(F7<0,"P0 Overdue",IF(F7<24,"P1 under 24h",IF(F7<72,"P2 under 72h","P3 later"))) | H7: Not started
A8: REQ01991 | B8: data_amendment | C8: 46325.708 | D8: 46328.667 | E8: M6 | F8: =(D8-$B$1)*24 | G8: =IF(F8<0,"P0 Overdue",IF(F8<24,"P1 under 24h",IF(F8<72,"P2 under 72h","P3 later"))) | H8: Not started
A9: REQ01994 | B9: signatory_change | C9: 46325.719 | D9: 46328.678 | E9: M3 | F9: =(D9-$B$1)*24 | G9: =IF(F9<0,"P0 Overdue",IF(F9<24,"P1 under 24h",IF(F9<72,"P2 under 72h","P3 later"))) | H9: Not started
A10: REQ01995 | B10: data_amendment | C10: 46325.733 | D10: 46328.691 | E10: M6 | F10: =(D10-$B$1)*24 | G10: =IF(F10<0,"P0 Overdue",IF(F10<24,"P1 under 24h",IF(F10<72,"P2 under 72h","P3 later"))) | H10: Not started
A11: REQ01997 | B11: signatory_change | C11: 46325.744 | D11: 46328.703 | E11: M2 | F11: =(D11-$B$1)*24 | G11: =IF(F11<0,"P0 Overdue",IF(F11<24,"P1 under 24h",IF(F11<72,"P2 under 72h","P3 later"))) | H11: Not started
A12: REQ01979 | B12: document_refresh | C12: 46325.656 | D12: 46329.406 | E12: M2 | F12: =(D12-$B$1)*24 | G12: =IF(F12<0,"P0 Overdue",IF(F12<24,"P1 under 24h",IF(F12<72,"P2 under 72h","P3 later"))) | H12: Not started
A13: REQ01982 | B13: document_refresh | C13: 46325.664 | D13: 46329.414 | E13: M4 | F13: =(D13-$B$1)*24 | G13: =IF(F13<0,"P0 Overdue",IF(F13<24,"P1 under 24h",IF(F13<72,"P2 under 72h","P3 later"))) | H13: Not started
A14: REQ01951 | B14: new_account | C14: 46325.526 | D14: 46329.442 | E14: M1 | F14: =(D14-$B$1)*24 | G14: =IF(F14<0,"P0 Overdue",IF(F14<24,"P1 under 24h",IF(F14<72,"P2 under 72h","P3 later"))) | H14: Not started
A15: REQ01957 | B15: new_account | C15: 46325.551 | D15: 46329.467 | E15: M5 | F15: =(D15-$B$1)*24 | G15: =IF(F15<0,"P0 Overdue",IF(F15<24,"P1 under 24h",IF(F15<72,"P2 under 72h","P3 later"))) | H15: Not started
... A23: REQ01977 | B23: new_account | C23: 46325.646 | D23: 46329.562 | E23: M6 | F23: =(D23-$B$1)*24 | G23: =IF(F23<0,"P0 Overdue",IF(F23<24,"P1 under 24h",IF(F23<72,"P2 under 72h","P3 later"))) | H23: Not started

Sheet Checker_Log
A1: log_id | B1: request_id | C1: maker_id | D1: checker_id | E1: result | F1: error_code | G1: checked_ts | H1: comment | I1: flag
A2: LOG0001 | B2: REQ01971 | C2: =IF(B2="","",IFERROR(INDEX(Data_Requests!$F$2:$F$2001,MATCH(B2,Data_Requests!$A$2:$A$2001,0)),"")) | I2: =IF(AND(C2<>"",D2<>"",C2=D2),"CHECK: maker equals checker","")
A3: LOG0002 | B3: REQ01980 | C3: =IF(B3="","",IFERROR(INDEX(Data_Requests!$F$2:$F$2001,MATCH(B3,Data_Requests!$A$2:$A$2001,0)),"")) | I3: =IF(AND(C3<>"",D3<>"",C3=D3),"CHECK: maker equals checker","")
A4: LOG0003 | B4: REQ01983 | C4: =IF(B4="","",IFERROR(INDEX(Data_Requests!$F$2:$F$2001,MATCH(B4,Data_Requests!$A$2:$A$2001,0)),"")) | I4: =IF(AND(C4<>"",D4<>"",C4=D4),"CHECK: maker equals checker","")
A5: LOG0004 | B5: REQ01988 | C5: =IF(B5="","",IFERROR(INDEX(Data_Requests!$F$2:$F$2001,MATCH(B5,Data_Requests!$A$2:$A$2001,0)),"")) | I5: =IF(AND(C5<>"",D5<>"",C5=D5),"CHECK: maker equals checker","")
A6: LOG0005 | B6: REQ01991 | C6: =IF(B6="","",IFERROR(INDEX(Data_Requests!$F$2:$F$2001,MATCH(B6,Data_Requests!$A$2:$A$2001,0)),"")) | I6: =IF(AND(C6<>"",D6<>"",C6=D6),"CHECK: maker equals checker","")
A7: LOG0006 | B7: REQ01994 | C7: =IF(B7="","",IFERROR(INDEX(Data_Requests!$F$2:$F$2001,MATCH(B7,Data_Requests!$A$2:$A$2001,0)),"")) | I7: =IF(AND(C7<>"",D7<>"",C7=D7),"CHECK: maker equals checker","")
A8: LOG0007 | B8: REQ01995 | C8: =IF(B8="","",IFERROR(INDEX(Data_Requests!$F$2:$F$2001,MATCH(B8,Data_Requests!$A$2:$A$2001,0)),"")) | I8: =IF(AND(C8<>"",D8<>"",C8=D8),"CHECK: maker equals checker","")
A9: LOG0008 | B9: REQ01997 | C9: =IF(B9="","",IFERROR(INDEX(Data_Requests!$F$2:$F$2001,MATCH(B9,Data_Requests!$A$2:$A$2001,0)),"")) | I9: =IF(AND(C9<>"",D9<>"",C9=D9),"CHECK: maker equals checker","")
A10: LOG0009 | B10: REQ01979 | C10: =IF(B10="","",IFERROR(INDEX(Data_Requests!$F$2:$F$2001,MATCH(B10,Data_Requests!$A$2:$A$2001,0)),"")) | I10: =IF(AND(C10<>"",D10<>"",C10=D10),"CHECK: maker equals checker","")
A11: LOG0010 | B11: REQ01982 | C11: =IF(B11="","",IFERROR(INDEX(Data_Requests!$F$2:$F$2001,MATCH(B11,Data_Requests!$A$2:$A$2001,0)),"")) | I11: =IF(AND(C11<>"",D11<>"",C11=D11),"CHECK: maker equals checker","")
A12: LOG0011 | B12: REQ01951 | C12: =IF(B12="","",IFERROR(INDEX(Data_Requests!$F$2:$F$2001,MATCH(B12,Data_Requests!$A$2:$A$2001,0)),"")) | I12: =IF(AND(C12<>"",D12<>"",C12=D12),"CHECK: maker equals checker","")
A13: LOG0012 | B13: REQ01957 | C13: =IF(B13="","",IFERROR(INDEX(Data_Requests!$F$2:$F$2001,MATCH(B13,Data_Requests!$A$2:$A$2001,0)),"")) | I13: =IF(AND(C13<>"",D13<>"",C13=D13),"CHECK: maker equals checker","")
... A21: LOG0020 | B21: REQ01977 | C21: =IF(B21="","",IFERROR(INDEX(Data_Requests!$F$2:$F$2001,MATCH(B21,Data_Requests!$A$2:$A$2001,0)),"")) | I21: =IF(AND(C21<>"",D21<>"",C21=D21),"CHECK: maker equals checker","")
A22: LOG0021 | C22: =IF(B22="","",IFERROR(INDEX(Data_Requests!$F$2:$F$2001,MATCH(B22,Data_Requests!$A$2:$A$2001,0)),""))
A23: LOG0022 | C23: =IF(B23="","",IFERROR(INDEX(Data_Requests!$F$2:$F$2001,MATCH(B23,Data_Requests!$A$2:$A$2001,0)),""))
A24: LOG0023 | C24: =IF(B24="","",IFERROR(INDEX(Data_Requests!$F$2:$F$2001,MATCH(B24,Data_Requests!$A$2:$A$2001,0)),""))
A25: LOG0024 | C25: =IF(B25="","",IFERROR(INDEX(Data_Requests!$F$2:$F$2001,MATCH(B25,Data_Requests!$A$2:$A$2001,0)),""))
A26: LOG0025 | C26: =IF(B26="","",IFERROR(INDEX(Data_Requests!$F$2:$F$2001,MATCH(B26,Data_Requests!$A$2:$A$2001,0)),""))
A27: LOG0026 | C27: =IF(B27="","",IFERROR(INDEX(Data_Requests!$F$2:$F$2001,MATCH(B27,Data_Requests!$A$2:$A$2001,0)),""))
A28: LOG0027 | C28: =IF(B28="","",IFERROR(INDEX(Data_Requests!$F$2:$F$2001,MATCH(B28,Data_Requests!$A$2:$A$2001,0)),""))
A29: LOG0028 | C29: =IF(B29="","",IFERROR(INDEX(Data_Requests!$F$2:$F$2001,MATCH(B29,Data_Requests!$A$2:$A$2001,0)),""))
A30: LOG0029 | C30: =IF(B30="","",IFERROR(INDEX(Data_Requests!$F$2:$F$2001,MATCH(B30,Data_Requests!$A$2:$A$2001,0)),""))
A31: LOG0030 | C31: =IF(B31="","",IFERROR(INDEX(Data_Requests!$F$2:$F$2001,MATCH(B31,Data_Requests!$A$2:$A$2001,0)),""))
A32: LOG0031 | C32: =IF(B32="","",IFERROR(INDEX(Data_Requests!$F$2:$F$2001,MATCH(B32,Data_Requests!$A$2:$A$2001,0)),""))
A33: LOG0032 | C33: =IF(B33="","",IFERROR(INDEX(Data_Requests!$F$2:$F$2001,MATCH(B33,Data_Requests!$A$2:$A$2001,0)),""))
... A201: LOG0200 | C201: =IF(B201="","",IFERROR(INDEX(Data_Requests!$F$2:$F$2001,MATCH(B201,Data_Requests!$A$2:$A$2001,0)),""))

Sheet KPI_Summary
A1: KPI summary
A2: Overall check | B2: =IF(COUNTIF(D6:D17,"CHECK")+COUNTIF(G21:G24,"CHECK")+COUNTIF(D31,"CHECK")=0,"ALL OK","REVIEW")
A3: All values are simulated. Escalation and error rates follow my severity and error-injection assumptions.
A5: Metric | B5: Excel formula | C5: DuckDB value | D5: Check
A6: Requests received | B6: =COUNTA(Data_Requests!$A$2:$A$2001) | C6: 2000 | D6: =IF(ABS(B6-C6)<0.0001,"OK","CHECK")
A7: Completed | B7: =COUNTIFS(Data_Requests!$J$2:$J$2001,"Completed") | C7: 1980 | D7: =IF(ABS(B7-C7)<0.0001,"OK","CHECK")
A8: Open | B8: =COUNTIFS(Data_Requests!$J$2:$J$2001,"Open") | C8: 20 | D8: =IF(ABS(B8-C8)<0.0001,"OK","CHECK")
A9: Median turnaround (hours) | B9: =MEDIAN(Data_Requests!$K$2:$K$2001) | C9: 1.905 | D9: =IF(ABS(B9-C9)<0.0001,"OK","CHECK")
A10: P90 turnaround (hours) | B10: =PERCENTILE(Data_Requests!$K$2:$K$2001,0.9) | C10: 5.93 | D10: =IF(ABS(B10-C10)<0.0001,"OK","CHECK")
A11: SLA breaches (count) | B11: =COUNTIFS(Data_Requests!$M$2:$M$2001,TRUE) | C11: 0 | D11: =IF(ABS(B11-C11)<0.0001,"OK","CHECK")
A12: SLA breach % of completed | B12: =COUNTIFS(Data_Requests!$M$2:$M$2001,TRUE)/COUNTIFS(Data_Requests!$J$2:$J$2001,"Completed") | C12: 0 | D12: =IF(ABS(B12-C12)<0.0001,"OK","CHECK")
A13: First-time-right % of completed | B13: =COUNTIFS(Data_Requests!$O$2:$O$2001,TRUE)/COUNTIFS(Data_Requests!$J$2:$J$2001,"Completed") | C13: 0.9459596 | D13: =IF(ABS(B13-C13)<0.0001,"OK","CHECK")
A14: Requests with an error | B14: =COUNTIFS(Data_Requests!$P$2:$P$2001,TRUE) | C14: 107 | D14: =IF(ABS(B14-C14)<0.0001,"OK","CHECK")
A15: Error rate (simulated, assumed injected rate) | B15: =COUNTIFS(Data_Requests!$P$2:$P$2001,TRUE)/COUNTA(Data_Requests!$A$2:$A$2001) | C15: 0.0535 | D15: =IF(ABS(B15-C15)<0.0001,"OK","CHECK")
A16: Escalated requests (matches fact_escalation) | B16: =COUNTIFS(Data_Requests!$Q$2:$Q$2001,TRUE) | C16: 993 | D16: =IF(ABS(B16-C16)<0.0001,"OK","CHECK")
A17: Total rework loops | B17: =SUM(Data_Requests!$N$2:$N$2001) | C17: 107 | D17: =IF(ABS(B17-C17)<0.0001,"OK","CHECK")
A19: By request type
A20: request_type | B20: Count (Excel) | C20: Count (DuckDB) | D20: Avg TAT h (Excel) | E20: Avg TAT h (DuckDB) | F20: Breach % (Excel) | G20: Check
A21: data_amendment | B21: =COUNTIFS(Data_Requests!$C$2:$C$2001,A21) | C21: 384 | D21: =AVERAGEIFS(Data_Requests!$K$2:$K$2001,Data_Requests!$C$2:$C$2001,A21) | E21: 2.3365963 | F21: =COUNTIFS(Data_Requests!$C$2:$C$2001,A21,Data_Requests!$M$2:$M$2001,TRUE)/COUNTIFS(Data_Requests!$C$2:$C$2001,A21,Data_Requests!$J$2:$J$2001,"Completed") | G21: =IF(AND(B21=C21,ABS(D21-E21)<0.001),"OK","CHECK")
A22: document_refresh | B22: =COUNTIFS(Data_Requests!$C$2:$C$2001,A22) | C22: 691 | D22: =AVERAGEIFS(Data_Requests!$K$2:$K$2001,Data_Requests!$C$2:$C$2001,A22) | E22: 2.6843066 | F22: =COUNTIFS(Data_Requests!$C$2:$C$2001,A22,Data_Requests!$M$2:$M$2001,TRUE)/COUNTIFS(Data_Requests!$C$2:$C$2001,A22,Data_Requests!$J$2:$J$2001,"Completed") | G22: =IF(AND(B22=C22,ABS(D22-E22)<0.001),"OK","CHECK")
A23: new_account | B23: =COUNTIFS(Data_Requests!$C$2:$C$2001,A23) | C23: 504 | D23: =AVERAGEIFS(Data_Requests!$K$2:$K$2001,Data_Requests!$C$2:$C$2001,A23) | E23: 3.0941566 | F23: =COUNTIFS(Data_Requests!$C$2:$C$2001,A23,Data_Requests!$M$2:$M$2001,TRUE)/COUNTIFS(Data_Requests!$C$2:$C$2001,A23,Data_Requests!$J$2:$J$2001,"Completed") | G23: =IF(AND(B23=C23,ABS(D23-E23)<0.001),"OK","CHECK")
A24: signatory_change | B24: =COUNTIFS(Data_Requests!$C$2:$C$2001,A24) | C24: 421 | D24: =AVERAGEIFS(Data_Requests!$K$2:$K$2001,Data_Requests!$C$2:$C$2001,A24) | E24: 2.8036603 | F24: =COUNTIFS(Data_Requests!$C$2:$C$2001,A24,Data_Requests!$M$2:$M$2001,TRUE)/COUNTIFS(Data_Requests!$C$2:$C$2001,A24,Data_Requests!$J$2:$J$2001,"Completed") | G24: =IF(AND(B24=C24,ABS(D24-E24)<0.001),"OK","CHECK")
A26: Open requests by priority band (Daily_Queue)
A27: P0 | B27: =COUNTIF(Daily_Queue!$G$4:$G$23,"P0*")
A28: P1 | B28: =COUNTIF(Daily_Queue!$G$4:$G$23,"P1*")
A29: P2 | B29: =COUNTIF(Daily_Queue!$G$4:$G$23,"P2*")
A30: P3 | B30: =COUNTIF(Daily_Queue!$G$4:$G$23,"P3*")
A31: Total in bands | B31: =SUM(B27:B30) | C31: =B8 | D31: =IF(B31=C31,"OK","CHECK")
A34: Lodgment and archive KPIs (simulated logs, Excel only)
A35: Lodgment entries | B35: =COUNTA(Lodgment_Log!B2:B201) | C35: No DuckDB equivalent
A36: Lodged | B36: =COUNTIF(Lodgment_Log!I2:I201,"Lodged") | C36: No DuckDB equivalent
A37: Lodged with a Complete check | B37: =COUNTIFS(Lodgment_Log!I2:I201,"Lodged",Lodgment_Log!F2:F201,"Complete") | C37: No DuckDB equivalent
A38: Average hours to lodge | B38: =AVERAGE(Lodgment_Log!J2:J201) | C38: No DuckDB equivalent
A39: Lodged within 4 hours (assumed target) | B39: =COUNTIFS(Lodgment_Log!I2:I201,"Lodged",Lodgment_Log!J2:J201,"<=4")/B36 | C39: No DuckDB equivalent
A40: Lodgment rows with a CHECK flag | B40: =COUNTIF(Lodgment_Log!K2:K201,"CHECK*") | C40: No DuckDB equivalent
A41: Archive entries | B41: =COUNTA(Archive_Manifest!B2:B201) | C41: No DuckDB equivalent
A42: Archive complete | B42: =COUNTIF(Archive_Manifest!I2:I201,"Complete") | C42: No DuckDB equivalent
A43: Archive completeness rate | B43: =B42/B41 | C43: No DuckDB equivalent
A44: Archive rows with a CHECK flag | B44: =COUNTIF(Archive_Manifest!M2:M201,"CHECK*") | C44: No DuckDB equivalent
A45: Checker_Log rows with a CHECK flag | B45: =COUNTIF(Checker_Log!I2:I201,"CHECK*") | C45: No DuckDB equivalent

Sheet Lodgment_Log
A1: lodgment_id | B1: request_id | C1: document_type | D1: received_ts | E1: checked_by | F1: check_result | G1: lodged_by | H1: lodged_ts | I1: system_status | J1: hours_to_lodge | K1: flag | L1: comment | N1: Lodgment status
A2: LDG0001 | B2: REQ00001 | C2: Signatory list | D2: 46300.375 | E2: C1 | F2: Complete | G2: M1 | H2: 46300.458 | I2: Lodged | J2: =IF(AND(D2<>"",H2<>""),ROUND((H2-D2)*24,1),"") | K2: =IF(AND(I2="Lodged",F2<>"Complete"),"CHECK: lodged without complete check","") | N2: Pending | O2: =COUNTIF($I$2:$I$201,N2)
A3: LDG0002 | B3: REQ00101 | C3: Board resolution | D3: 46301.417 | E3: C2 | F3: Complete | G3: M2 | H3: 46301.542 | I3: Lodged | J3: =IF(AND(D3<>"",H3<>""),ROUND((H3-D3)*24,1),"") | K3: =IF(AND(I3="Lodged",F3<>"Complete"),"CHECK: lodged without complete check","") | N3: Lodged | O3: =COUNTIF($I$2:$I$201,N3)
A4: LDG0003 | B4: REQ00201 | C4: ID document | D4: 46302.458 | E4: C3 | F4: Complete | G4: M3 | H4: 46302.625 | I4: Lodged | J4: =IF(AND(D4<>"",H4<>""),ROUND((H4-D4)*24,1),"") | K4: =IF(AND(I4="Lodged",F4<>"Complete"),"CHECK: lodged without complete check","") | N4: Returned to client | O4: =COUNTIF($I$2:$I$201,N4)
A5: LDG0004 | B5: REQ00301 | C5: Account opening form | D5: 46303.5 | E5: C4 | F5: Complete | G5: M4 | H5: 46303.708 | I5: Lodged | J5: =IF(AND(D5<>"",H5<>""),ROUND((H5-D5)*24,1),"") | K5: =IF(AND(I5="Lodged",F5<>"Complete"),"CHECK: lodged without complete check","")
A6: LDG0005 | B6: REQ00401 | C6: Signature card | D6: 46304.542 | E6: C1 | F6: Complete | G6: M5 | H6: 46304.792 | I6: Lodged | J6: =IF(AND(D6<>"",H6<>""),ROUND((H6-D6)*24,1),"") | K6: =IF(AND(I6="Lodged",F6<>"Complete"),"CHECK: lodged without complete check","") | N6: Rows with CHECK flag | O6: =COUNTIF($K$2:$K$201,"CHECK*")
A7: LDG0006 | B7: REQ00501 | C7: Address proof | D7: 46307.583 | E7: C2 | F7: Complete | G7: M6 | H7: 46307.667 | I7: Lodged | J7: =IF(AND(D7<>"",H7<>""),ROUND((H7-D7)*24,1),"") | K7: =IF(AND(I7="Lodged",F7<>"Complete"),"CHECK: lodged without complete check","")
A8: LDG0007 | B8: REQ00601 | C8: Signatory list | D8: 46308.375 | E8: C3 | F8: Complete | G8: M7 | H8: 46308.5 | I8: Lodged | J8: =IF(AND(D8<>"",H8<>""),ROUND((H8-D8)*24,1),"") | K8: =IF(AND(I8="Lodged",F8<>"Complete"),"CHECK: lodged without complete check","") | N8: Simulated log. Checker IDs C1-C4 and maker IDs M1-M8 are assumptions.
A9: LDG0008 | B9: REQ00701 | C9: Board resolution | D9: 46309.417 | E9: C4 | F9: Complete | G9: M8 | H9: 46309.583 | I9: Lodged | J9: =IF(AND(D9<>"",H9<>""),ROUND((H9-D9)*24,1),"") | K9: =IF(AND(I9="Lodged",F9<>"Complete"),"CHECK: lodged without complete check","")
A10: LDG0009 | B10: REQ00801 | C10: ID document | D10: 46310.458 | E10: C1 | F10: Complete | G10: M1 | H10: 46310.667 | I10: Lodged | J10: =IF(AND(D10<>"",H10<>""),ROUND((H10-D10)*24,1),"") | K10: =IF(AND(I10="Lodged",F10<>"Complete"),"CHECK: lodged without complete check","")
A11: LDG0010 | B11: REQ00901 | C11: Account opening form | D11: 46311.5 | E11: C2 | F11: Complete | G11: M2 | H11: 46311.75 | I11: Lodged | J11: =IF(AND(D11<>"",H11<>""),ROUND((H11-D11)*24,1),"") | K11: =IF(AND(I11="Lodged",F11<>"Complete"),"CHECK: lodged without complete check","")
A12: LDG0011 | B12: REQ01001 | C12: Signature card | D12: 46314.542 | E12: C3 | F12: Complete | G12: M3 | H12: 46314.625 | I12: Lodged | J12: =IF(AND(D12<>"",H12<>""),ROUND((H12-D12)*24,1),"") | K12: =IF(AND(I12="Lodged",F12<>"Complete"),"CHECK: lodged without complete check","")
A13: LDG0012 | B13: REQ01101 | C13: Address proof | D13: 46315.583 | E13: C4 | F13: Complete | G13: M4 | H13: 46315.708 | I13: Lodged | J13: =IF(AND(D13<>"",H13<>""),ROUND((H13-D13)*24,1),"") | K13: =IF(AND(I13="Lodged",F13<>"Complete"),"CHECK: lodged without complete check","")
A14: LDG0013 | B14: REQ01201 | C14: Signatory list | D14: 46316.375 | E14: C1 | F14: Incomplete | G14: M5 | I14: Returned to client | J14: =IF(AND(D14<>"",H14<>""),ROUND((H14-D14)*24,1),"") | K14: =IF(AND(I14="Lodged",F14<>"Complete"),"CHECK: lodged without complete check","") | L14: Returned: required document missing (simulated).
A15: LDG0014 | B15: REQ01301 | C15: Board resolution | D15: 46317.417 | E15: C2 | F15: Rejected | G15: M6 | I15: Returned to client | J15: =IF(AND(D15<>"",H15<>""),ROUND((H15-D15)*24,1),"") | K15: =IF(AND(I15="Lodged",F15<>"Complete"),"CHECK: lodged without complete check","") | L15: Returned: signatory authority not evidenced (simulated).
A16: LDG0015 | B16: REQ01401 | C16: ID document | D16: 46318.458 | E16: C3 | F16: Complete | G16: M7 | I16: Pending | J16: =IF(AND(D16<>"",H16<>""),ROUND((H16-D16)*24,1),"") | K16: =IF(AND(I16="Lodged",F16<>"Complete"),"CHECK: lodged without complete check","") | L16: Awaiting client document (simulated).
A17: LDG0016 | B17: REQ01501 | C17: Account opening form | D17: 46321.5 | E17: C4 | F17: Incomplete | G17: M8 | H17: 46321.583 | I17: Lodged | J17: =IF(AND(D17<>"",H17<>""),ROUND((H17-D17)*24,1),"") | K17: =IF(AND(I17="Lodged",F17<>"Complete"),"CHECK: lodged without complete check","") | L17: Deliberate test case: lodged without a complete check; the flag should fire.
A18: LDG0017 | B18: REQ01601 | C18: Signature card | D18: 46322.542 | E18: C1 | F18: Complete | G18: M1 | H18: 46322.667 | I18: Lodged | J18: =IF(AND(D18<>"",H18<>""),ROUND((H18-D18)*24,1),"") | K18: =IF(AND(I18="Lodged",F18<>"Complete"),"CHECK: lodged without complete check","")
A19: LDG0018 | B19: REQ01701 | C19: Address proof | D19: 46323.583 | E19: C2 | F19: Complete | G19: M2 | H19: 46323.75 | I19: Lodged | J19: =IF(AND(D19<>"",H19<>""),ROUND((H19-D19)*24,1),"") | K19: =IF(AND(I19="Lodged",F19<>"Complete"),"CHECK: lodged without complete check","")
A20: LDG0019 | J20: =IF(AND(D20<>"",H20<>""),ROUND((H20-D20)*24,1),"") | K20: =IF(AND(I20="Lodged",F20<>"Complete"),"CHECK: lodged without complete check","")
A21: LDG0020 | J21: =IF(AND(D21<>"",H21<>""),ROUND((H21-D21)*24,1),"") | K21: =IF(AND(I21="Lodged",F21<>"Complete"),"CHECK: lodged without complete check","")
A22: LDG0021 | J22: =IF(AND(D22<>"",H22<>""),ROUND((H22-D22)*24,1),"") | K22: =IF(AND(I22="Lodged",F22<>"Complete"),"CHECK: lodged without complete check","")
A23: LDG0022 | J23: =IF(AND(D23<>"",H23<>""),ROUND((H23-D23)*24,1),"") | K23: =IF(AND(I23="Lodged",F23<>"Complete"),"CHECK: lodged without complete check","")
A24: LDG0023 | J24: =IF(AND(D24<>"",H24<>""),ROUND((H24-D24)*24,1),"") | K24: =IF(AND(I24="Lodged",F24<>"Complete"),"CHECK: lodged without complete check","")
A25: LDG0024 | J25: =IF(AND(D25<>"",H25<>""),ROUND((H25-D25)*24,1),"") | K25: =IF(AND(I25="Lodged",F25<>"Complete"),"CHECK: lodged without complete check","")
A26: LDG0025 | J26: =IF(AND(D26<>"",H26<>""),ROUND((H26-D26)*24,1),"") | K26: =IF(AND(I26="Lodged",F26<>"Complete"),"CHECK: lodged without complete check","")
A27: LDG0026 | J27: =IF(AND(D27<>"",H27<>""),ROUND((H27-D27)*24,1),"") | K27: =IF(AND(I27="Lodged",F27<>"Complete"),"CHECK: lodged without complete check","")
A28: LDG0027 | J28: =IF(AND(D28<>"",H28<>""),ROUND((H28-D28)*24,1),"") | K28: =IF(AND(I28="Lodged",F28<>"Complete"),"CHECK: lodged without complete check","")
A29: LDG0028 | J29: =IF(AND(D29<>"",H29<>""),ROUND((H29-D29)*24,1),"") | K29: =IF(AND(I29="Lodged",F29<>"Complete"),"CHECK: lodged without complete check","")
A30: LDG0029 | J30: =IF(AND(D30<>"",H30<>""),ROUND((H30-D30)*24,1),"") | K30: =IF(AND(I30="Lodged",F30<>"Complete"),"CHECK: lodged without complete check","")
A31: LDG0030 | J31: =IF(AND(D31<>"",H31<>""),ROUND((H31-D31)*24,1),"") | K31: =IF(AND(I31="Lodged",F31<>"Complete"),"CHECK: lodged without complete check","")
... A201: LDG0200 | J201: =IF(AND(D201<>"",H201<>""),ROUND((H201-D201)*24,1),"") | K201: =IF(AND(I201="Lodged",F201<>"Complete"),"CHECK: lodged without complete check","")

Sheet Archive_Manifest
A1: archive_id | B1: request_id | C1: document_type | D1: doc_date | E1: version | F1: file_name | G1: docs_expected | H1: docs_present | I1: completeness | J1: retention_note | K1: archived_by | L1: archived_date | M1: flag | O1: File naming convention
A2: ARC0001 | B2: REQ00001 | C2: Signatory list | D2: 46300 | E2: 1 | F2: =IF(OR(B2="",C2="",D2="",E2=""),"",B2&"_"&SUBSTITUTE(C2," ","-")&"_"&TEXT(D2,"yyyymmdd")&"_v"&E2) | G2: 2 | H2: 2 | I2: =IF(OR(G2="",H2=""),"",IF(H2>=G2,"Complete","Incomplete")) | J2: =IF(B2="","","Retention period per bank policy; not defined in this simulation") | K2: M1 | L2: 46301 | M2: =IF(AND(K2<>"",I2<>"Complete"),"CHECK: archived while incomplete","") | O2: request_id_document-type_YYYYMMDD_vN
A3: ARC0002 | B3: REQ00101 | C3: Board resolution | D3: 46301 | E3: 1 | F3: =IF(OR(B3="",C3="",D3="",E3=""),"",B3&"_"&SUBSTITUTE(C3," ","-")&"_"&TEXT(D3,"yyyymmdd")&"_v"&E3) | G3: 3 | H3: 3 | I3: =IF(OR(G3="",H3=""),"",IF(H3>=G3,"Complete","Incomplete")) | J3: =IF(B3="","","Retention period per bank policy; not defined in this simulation") | K3: M2 | L3: 46302 | M3: =IF(AND(K3<>"",I3<>"Complete"),"CHECK: archived while incomplete","") | O3: Example: REQ01971_Signatory-list_20261030_v1
A4: ARC0003 | B4: REQ00201 | C4: ID document | D4: 46302 | E4: 1 | F4: =IF(OR(B4="",C4="",D4="",E4=""),"",B4&"_"&SUBSTITUTE(C4," ","-")&"_"&TEXT(D4,"yyyymmdd")&"_v"&E4) | G4: 2 | H4: 2 | I4: =IF(OR(G4="",H4=""),"",IF(H4>=G4,"Complete","Incomplete")) | J4: =IF(B4="","","Retention period per bank policy; not defined in this simulation") | K4: M3 | L4: 46303 | M4: =IF(AND(K4<>"",I4<>"Complete"),"CHECK: archived while incomplete","") | O4: Archive only when completeness = Complete.
A5: ARC0004 | B5: REQ00301 | C5: Account opening form | D5: 46303 | E5: 1 | F5: =IF(OR(B5="",C5="",D5="",E5=""),"",B5&"_"&SUBSTITUTE(C5," ","-")&"_"&TEXT(D5,"yyyymmdd")&"_v"&E5) | G5: 3 | H5: 3 | I5: =IF(OR(G5="",H5=""),"",IF(H5>=G5,"Complete","Incomplete")) | J5: =IF(B5="","","Retention period per bank policy; not defined in this simulation") | K5: M4 | L5: 46304 | M5: =IF(AND(K5<>"",I5<>"Complete"),"CHECK: archived while incomplete","") | O5: Retention period: set by bank policy, not defined here.
A6: ARC0005 | B6: REQ00401 | C6: Signature card | D6: 46304 | E6: 1 | F6: =IF(OR(B6="",C6="",D6="",E6=""),"",B6&"_"&SUBSTITUTE(C6," ","-")&"_"&TEXT(D6,"yyyymmdd")&"_v"&E6) | G6: 2 | H6: 2 | I6: =IF(OR(G6="",H6=""),"",IF(H6>=G6,"Complete","Incomplete")) | J6: =IF(B6="","","Retention period per bank policy; not defined in this simulation") | K6: M5 | L6: 46305 | M6: =IF(AND(K6<>"",I6<>"Complete"),"CHECK: archived while incomplete","") | O6: Simulated manifest. Not Citi data.
A7: ARC0006 | B7: REQ00501 | C7: Address proof | D7: 46307 | E7: 2 | F7: =IF(OR(B7="",C7="",D7="",E7=""),"",B7&"_"&SUBSTITUTE(C7," ","-")&"_"&TEXT(D7,"yyyymmdd")&"_v"&E7) | G7: 3 | H7: 3 | I7: =IF(OR(G7="",H7=""),"",IF(H7>=G7,"Complete","Incomplete")) | J7: =IF(B7="","","Retention period per bank policy; not defined in this simulation") | K7: M6 | L7: 46308 | M7: =IF(AND(K7<>"",I7<>"Complete"),"CHECK: archived while incomplete","")
A8: ARC0007 | B8: REQ00601 | C8: Signatory list | D8: 46308 | E8: 1 | F8: =IF(OR(B8="",C8="",D8="",E8=""),"",B8&"_"&SUBSTITUTE(C8," ","-")&"_"&TEXT(D8,"yyyymmdd")&"_v"&E8) | G8: 2 | H8: 2 | I8: =IF(OR(G8="",H8=""),"",IF(H8>=G8,"Complete","Incomplete")) | J8: =IF(B8="","","Retention period per bank policy; not defined in this simulation") | K8: M7 | L8: 46309 | M8: =IF(AND(K8<>"",I8<>"Complete"),"CHECK: archived while incomplete","")
A9: ARC0008 | B9: REQ00701 | C9: Board resolution | D9: 46309 | E9: 1 | F9: =IF(OR(B9="",C9="",D9="",E9=""),"",B9&"_"&SUBSTITUTE(C9," ","-")&"_"&TEXT(D9,"yyyymmdd")&"_v"&E9) | G9: 3 | H9: 3 | I9: =IF(OR(G9="",H9=""),"",IF(H9>=G9,"Complete","Incomplete")) | J9: =IF(B9="","","Retention period per bank policy; not defined in this simulation") | K9: M8 | L9: 46310 | M9: =IF(AND(K9<>"",I9<>"Complete"),"CHECK: archived while incomplete","")
A10: ARC0009 | B10: REQ00801 | C10: ID document | D10: 46310 | E10: 1 | F10: =IF(OR(B10="",C10="",D10="",E10=""),"",B10&"_"&SUBSTITUTE(C10," ","-")&"_"&TEXT(D10,"yyyymmdd")&"_v"&E10) | G10: 2 | H10: 2 | I10: =IF(OR(G10="",H10=""),"",IF(H10>=G10,"Complete","Incomplete")) | J10: =IF(B10="","","Retention period per bank policy; not defined in this simulation") | K10: M1 | L10: 46311 | M10: =IF(AND(K10<>"",I10<>"Complete"),"CHECK: archived while incomplete","")
A11: ARC0010 | B11: REQ00901 | C11: Account opening form | D11: 46311 | E11: 1 | F11: =IF(OR(B11="",C11="",D11="",E11=""),"",B11&"_"&SUBSTITUTE(C11," ","-")&"_"&TEXT(D11,"yyyymmdd")&"_v"&E11) | G11: 3 | H11: 3 | I11: =IF(OR(G11="",H11=""),"",IF(H11>=G11,"Complete","Incomplete")) | J11: =IF(B11="","","Retention period per bank policy; not defined in this simulation") | K11: M2 | L11: 46312 | M11: =IF(AND(K11<>"",I11<>"Complete"),"CHECK: archived while incomplete","")
A12: ARC0011 | B12: REQ01001 | C12: Signature card | D12: 46314 | E12: 1 | F12: =IF(OR(B12="",C12="",D12="",E12=""),"",B12&"_"&SUBSTITUTE(C12," ","-")&"_"&TEXT(D12,"yyyymmdd")&"_v"&E12) | G12: 2 | H12: 2 | I12: =IF(OR(G12="",H12=""),"",IF(H12>=G12,"Complete","Incomplete")) | J12: =IF(B12="","","Retention period per bank policy; not defined in this simulation") | K12: M3 | L12: 46315 | M12: =IF(AND(K12<>"",I12<>"Complete"),"CHECK: archived while incomplete","")
A13: ARC0012 | B13: REQ01101 | C13: Address proof | D13: 46315 | E13: 1 | F13: =IF(OR(B13="",C13="",D13="",E13=""),"",B13&"_"&SUBSTITUTE(C13," ","-")&"_"&TEXT(D13,"yyyymmdd")&"_v"&E13) | G13: 3 | H13: 3 | I13: =IF(OR(G13="",H13=""),"",IF(H13>=G13,"Complete","Incomplete")) | J13: =IF(B13="","","Retention period per bank policy; not defined in this simulation") | K13: M4 | L13: 46316 | M13: =IF(AND(K13<>"",I13<>"Complete"),"CHECK: archived while incomplete","")
A14: ARC0013 | B14: REQ01601 | C14: Signature card | D14: 46322 | E14: 1 | F14: =IF(OR(B14="",C14="",D14="",E14=""),"",B14&"_"&SUBSTITUTE(C14," ","-")&"_"&TEXT(D14,"yyyymmdd")&"_v"&E14) | G14: 2 | H14: 1 | I14: =IF(OR(G14="",H14=""),"",IF(H14>=G14,"Complete","Incomplete")) | J14: =IF(B14="","","Retention period per bank policy; not defined in this simulation") | M14: =IF(AND(K14<>"",I14<>"Complete"),"CHECK: archived while incomplete","")
A15: ARC0014 | B15: REQ01701 | C15: Address proof | D15: 46323 | E15: 1 | F15: =IF(OR(B15="",C15="",D15="",E15=""),"",B15&"_"&SUBSTITUTE(C15," ","-")&"_"&TEXT(D15,"yyyymmdd")&"_v"&E15) | G15: 3 | H15: 2 | I15: =IF(OR(G15="",H15=""),"",IF(H15>=G15,"Complete","Incomplete")) | J15: =IF(B15="","","Retention period per bank policy; not defined in this simulation") | K15: M2 | L15: 46324 | M15: =IF(AND(K15<>"",I15<>"Complete"),"CHECK: archived while incomplete","")
A16: ARC0015 | F16: =IF(OR(B16="",C16="",D16="",E16=""),"",B16&"_"&SUBSTITUTE(C16," ","-")&"_"&TEXT(D16,"yyyymmdd")&"_v"&E16) | I16: =IF(OR(G16="",H16=""),"",IF(H16>=G16,"Complete","Incomplete")) | J16: =IF(B16="","","Retention period per bank policy; not defined in this simulation") | M16: =IF(AND(K16<>"",I16<>"Complete"),"CHECK: archived while incomplete","")
A17: ARC0016 | F17: =IF(OR(B17="",C17="",D17="",E17=""),"",B17&"_"&SUBSTITUTE(C17," ","-")&"_"&TEXT(D17,"yyyymmdd")&"_v"&E17) | I17: =IF(OR(G17="",H17=""),"",IF(H17>=G17,"Complete","Incomplete")) | J17: =IF(B17="","","Retention period per bank policy; not defined in this simulation") | M17: =IF(AND(K17<>"",I17<>"Complete"),"CHECK: archived while incomplete","")
A18: ARC0017 | F18: =IF(OR(B18="",C18="",D18="",E18=""),"",B18&"_"&SUBSTITUTE(C18," ","-")&"_"&TEXT(D18,"yyyymmdd")&"_v"&E18) | I18: =IF(OR(G18="",H18=""),"",IF(H18>=G18,"Complete","Incomplete")) | J18: =IF(B18="","","Retention period per bank policy; not defined in this simulation") | M18: =IF(AND(K18<>"",I18<>"Complete"),"CHECK: archived while incomplete","")
A19: ARC0018 | F19: =IF(OR(B19="",C19="",D19="",E19=""),"",B19&"_"&SUBSTITUTE(C19," ","-")&"_"&TEXT(D19,"yyyymmdd")&"_v"&E19) | I19: =IF(OR(G19="",H19=""),"",IF(H19>=G19,"Complete","Incomplete")) | J19: =IF(B19="","","Retention period per bank policy; not defined in this simulation") | M19: =IF(AND(K19<>"",I19<>"Complete"),"CHECK: archived while incomplete","")
A20: ARC0019 | F20: =IF(OR(B20="",C20="",D20="",E20=""),"",B20&"_"&SUBSTITUTE(C20," ","-")&"_"&TEXT(D20,"yyyymmdd")&"_v"&E20) | I20: =IF(OR(G20="",H20=""),"",IF(H20>=G20,"Complete","Incomplete")) | J20: =IF(B20="","","Retention period per bank policy; not defined in this simulation") | M20: =IF(AND(K20<>"",I20<>"Complete"),"CHECK: archived while incomplete","")
A21: ARC0020 | F21: =IF(OR(B21="",C21="",D21="",E21=""),"",B21&"_"&SUBSTITUTE(C21," ","-")&"_"&TEXT(D21,"yyyymmdd")&"_v"&E21) | I21: =IF(OR(G21="",H21=""),"",IF(H21>=G21,"Complete","Incomplete")) | J21: =IF(B21="","","Retention period per bank policy; not defined in this simulation") | M21: =IF(AND(K21<>"",I21<>"Complete"),"CHECK: archived while incomplete","")
A22: ARC0021 | F22: =IF(OR(B22="",C22="",D22="",E22=""),"",B22&"_"&SUBSTITUTE(C22," ","-")&"_"&TEXT(D22,"yyyymmdd")&"_v"&E22) | I22: =IF(OR(G22="",H22=""),"",IF(H22>=G22,"Complete","Incomplete")) | J22: =IF(B22="","","Retention period per bank policy; not defined in this simulation") | M22: =IF(AND(K22<>"",I22<>"Complete"),"CHECK: archived while incomplete","")
A23: ARC0022 | F23: =IF(OR(B23="",C23="",D23="",E23=""),"",B23&"_"&SUBSTITUTE(C23," ","-")&"_"&TEXT(D23,"yyyymmdd")&"_v"&E23) | I23: =IF(OR(G23="",H23=""),"",IF(H23>=G23,"Complete","Incomplete")) | J23: =IF(B23="","","Retention period per bank policy; not defined in this simulation") | M23: =IF(AND(K23<>"",I23<>"Complete"),"CHECK: archived while incomplete","")
A24: ARC0023 | F24: =IF(OR(B24="",C24="",D24="",E24=""),"",B24&"_"&SUBSTITUTE(C24," ","-")&"_"&TEXT(D24,"yyyymmdd")&"_v"&E24) | I24: =IF(OR(G24="",H24=""),"",IF(H24>=G24,"Complete","Incomplete")) | J24: =IF(B24="","","Retention period per bank policy; not defined in this simulation") | M24: =IF(AND(K24<>"",I24<>"Complete"),"CHECK: archived while incomplete","")
A25: ARC0024 | F25: =IF(OR(B25="",C25="",D25="",E25=""),"",B25&"_"&SUBSTITUTE(C25," ","-")&"_"&TEXT(D25,"yyyymmdd")&"_v"&E25) | I25: =IF(OR(G25="",H25=""),"",IF(H25>=G25,"Complete","Incomplete")) | J25: =IF(B25="","","Retention period per bank policy; not defined in this simulation") | M25: =IF(AND(K25<>"",I25<>"Complete"),"CHECK: archived while incomplete","")
A26: ARC0025 | F26: =IF(OR(B26="",C26="",D26="",E26=""),"",B26&"_"&SUBSTITUTE(C26," ","-")&"_"&TEXT(D26,"yyyymmdd")&"_v"&E26) | I26: =IF(OR(G26="",H26=""),"",IF(H26>=G26,"Complete","Incomplete")) | J26: =IF(B26="","","Retention period per bank policy; not defined in this simulation") | M26: =IF(AND(K26<>"",I26<>"Complete"),"CHECK: archived while incomplete","")
A27: ARC0026 | F27: =IF(OR(B27="",C27="",D27="",E27=""),"",B27&"_"&SUBSTITUTE(C27," ","-")&"_"&TEXT(D27,"yyyymmdd")&"_v"&E27) | I27: =IF(OR(G27="",H27=""),"",IF(H27>=G27,"Complete","Incomplete")) | J27: =IF(B27="","","Retention period per bank policy; not defined in this simulation") | M27: =IF(AND(K27<>"",I27<>"Complete"),"CHECK: archived while incomplete","")
... A201: ARC0200 | F201: =IF(OR(B201="",C201="",D201="",E201=""),"",B201&"_"&SUBSTITUTE(C201," ","-")&"_"&TEXT(D201,"yyyymmdd")&"_v"&E201) | I201: =IF(OR(G201="",H201=""),"",IF(H201>=G201,"Complete","Incomplete")) | J201: =IF(B201="","","Retention period per bank policy; not defined in this simulation") | M201: =IF(AND(K201<>"",I201<>"Complete"),"CHECK: archived while incomplete","")
